<?xml version="1.0" ?>
<sdf version="1.8">
    <world name="car_world">
        <physics name="1ms" type="ignored">
            <max_step_size>0.001</max_step_size>
            <real_time_factor>1.0</real_time_factor>
        </physics>
        <plugin filename="gz-sim-physics-system" name="gz::sim::systems::Physics"/>
        <plugin filename="gz-sim-user-commands-system" name="gz::sim::systems::UserCommands"/>
        <plugin filename="gz-sim-scene-broadcaster-system" name="gz::sim::systems::SceneBroadcaster"/>

        <plugin filename="gz-sim-sensors-system" name="gz::sim::systems::Sensors">
            <render_engine>ogre2</render_engine>
        </plugin>

        <light type="directional" name="sun">
            <cast_shadows>true</cast_shadows>
            <pose>0 0 10 0 0 0</pose>
            <diffuse>0.8 0.8 0.8 1</diffuse>
            <specular>0.2 0.2 0.2 1</specular>
            <direction>-0.5 0.1 -0.9</direction>
        </light>

        <model name="ground_plane">
            <static>true</static>
            <link name="link">
                <collision name="collision">
                    <geometry>
                        <plane>
                            <normal>0 0 1</normal>
                            <size>100 100</size>
                        </plane>
                    </geometry>
                </collision>
                <visual name="visual">
                    <geometry>
                        <plane>
                            <normal>0 0 1</normal>
                            <size>100 100</size>
                        </plane>
                    </geometry>
                    <material>
                        <ambient>0.8 0.8 0.8 1</ambient>
                        <diffuse>0.8 0.8 0.8 1</diffuse>
                        <specular>0.8 0.8 0.8 1</specular>
                    </material>
                </visual>
            </link>
        </model>

        <model name="red_wall">
    <static>true</static>
    <pose>5 0 0.25 0 0 0</pose> <link name="box_link">
        <collision name="collision">
            <geometry>
                <box>
                    <size>0.5 10.0 1</size> </box>
            </geometry>
        </collision>
        <visual name="visual">
            <geometry>
                <box>
                    <size>0.5 10.0 0.5</size>
                </box>
            </geometry>
            <material>
                <ambient>1 0 0 1</ambient>
                <diffuse>1 0 0 1</diffuse>
                <specular>0.1 0.1 0.1 1</specular>
            </material>
        </visual>
    </link>
</model>

        <model name="cylinder_obstacle">
            <pose>3 3 0.5 0 0 0</pose>
            <link name="link">
                <collision name="col"><geometry><cylinder><radius>0.5</radius><length>1.0</length></cylinder></geometry></collision>
                <visual name="vis"><geometry><cylinder><radius>0.5</radius><length>1.0</length></cylinder></geometry>
                    <material><ambient>0 1 0 1</ambient><diffuse>0 1 0 1</diffuse></material>
                </visual>
            </link>
        </model>

        <model name="sphere_obstacle">
            <pose>3 -3 0.5 0 0 0</pose>
            <link name="link">
                <collision name="col"><geometry><sphere><radius>0.5</radius></sphere></geometry></collision>
                <visual name="vis"><geometry><sphere><radius>0.5</radius></sphere></geometry>
                    <material><ambient>0 0 1 1</ambient><diffuse>0 0 1 1</diffuse></material>
                </visual>
            </link>
        </model>

        <model name='four_wheeled_robot' canonical_link='chassis'>
            <pose>0 0 0.4 0 0 0</pose>

            <link name='chassis'>
                <pose relative_to='__model__'>0.5 0 0.4 0 0 0</pose>
                <inertial>
                    <mass>1.14395</mass>
                    <inertia>
                        <ixx>0.095329</ixx>
                        <ixy>0</ixy>
                        <ixz>0</ixz>
                        <iyy>0.381317</iyy>
                        <iyz>0</iyz>
                        <izz>0.476646</izz>
                    </inertia>
                </inertial>
                <visual name='visual'>
                    <geometry>
                        <box>
                            <size>2.0 1.0 0.5</size>
                        </box>
                    </geometry>
                    <material>
                        <ambient>0.0 0.5 1.0 1</ambient>
                        <diffuse>0.0 0.5 1.0 1</diffuse>
                    </material>
                </visual>
                <collision name='collision'>
                    <geometry>
                        <box>
                            <size>2.0 1.0 0.5</size>
                        </box>
                    </geometry>
                </collision>
            </link>

            <link name='left_front_wheel'>
                <pose relative_to="chassis">0.6 0.6 -0.1 -1.5707 0 0</pose>
                <inertial>
                    <mass>1</mass>
                    <inertia>
                        <ixx>0.043333</ixx>
                        <ixy>0</ixy>
                        <ixz>0</ixz>
                        <iyy>0.043333</iyy>
                        <iyz>0</iyz>
                        <izz>0.08</izz>
                    </inertia>
                </inertial>
                <visual name='visual'>
                    <geometry><cylinder><radius>0.4</radius><length>0.2</length></cylinder></geometry>
                    <material><ambient>0.2 0.2 0.2 1</ambient><diffuse>0.2 0.2 0.2 1</diffuse></material>
                </visual>
                <collision name='collision'>
                    <geometry><cylinder><radius>0.4</radius><length>0.2</length></cylinder></geometry>
                </collision>
            </link>

            <link name='right_front_wheel'>
                <pose relative_to="chassis">0.6 -0.6 -0.1 -1.5707 0 0</pose>
                <inertial>
                    <mass>1</mass>
                    <inertia>
                        <ixx>0.043333</ixx><ixy>0</ixy><ixz>0</ixz><iyy>0.043333</iyy><iyz>0</iyz><izz>0.08</izz>
                    </inertia>
                </inertial>
                <visual name='visual'>
                    <geometry><cylinder><radius>0.4</radius><length>0.2</length></cylinder></geometry>
                    <material><ambient>0.2 0.2 0.2 1</ambient><diffuse>0.2 0.2 0.2 1</diffuse></material>
                </visual>
                <collision name='collision'>
                    <geometry><cylinder><radius>0.4</radius><length>0.2</length></cylinder></geometry>
                </collision>
            </link>

            <link name='left_rear_wheel'>
                <pose relative_to="chassis">-0.6 0.6 -0.1 -1.5707 0 0</pose>
                <inertial>
                    <mass>1</mass>
                    <inertia>
                        <ixx>0.043333</ixx><ixy>0</ixy><ixz>0</ixz><iyy>0.043333</iyy><iyz>0</iyz><izz>0.08</izz>
                    </inertia>
                </inertial>
                <visual name='visual'>
                    <geometry><cylinder><radius>0.4</radius><length>0.2</length></cylinder></geometry>
                    <material><ambient>0.2 0.2 0.2 1</ambient><diffuse>0.2 0.2 0.2 1</diffuse></material>
                </visual>
                <collision name='collision'>
                    <geometry><cylinder><radius>0.4</radius><length>0.2</length></cylinder></geometry>
                </collision>
            </link>

            <link name='right_rear_wheel'>
                <pose relative_to="chassis">-0.6 -0.6 -0.1 -1.5707 0 0</pose>
                <inertial>
                    <mass>1</mass>
                    <inertia>
                        <ixx>0.043333</ixx><ixy>0</ixy><ixz>0</ixz><iyy>0.043333</iyy><iyz>0</iyz><izz>0.08</izz>
                    </inertia>
                </inertial>
                <visual name='visual'>
                    <geometry><cylinder><radius>0.4</radius><length>0.2</length></cylinder></geometry>
                    <material><ambient>0.2 0.2 0.2 1</ambient><diffuse>0.2 0.2 0.2 1</diffuse></material>
                </visual>
                <collision name='collision'>
                    <geometry><cylinder><radius>0.4</radius><length>0.2</length></cylinder></geometry>
                </collision>
            </link>

            <joint name='left_front_wheel_joint' type='revolute'>
                <parent>chassis</parent>
                <child>left_front_wheel</child>
                <axis>
                    <xyz>0 0 1</xyz>
                    <limit><lower>-1.79769e+308</lower><upper>1.79769e+308</upper></limit>
                </axis>
            </joint>

            <joint name='right_front_wheel_joint' type='revolute'>
                <parent>chassis</parent>
                <child>right_front_wheel</child>
                <axis>
                    <xyz>0 0 1</xyz>
                    <limit><lower>-1.79769e+308</lower><upper>1.79769e+308</upper></limit>
                </axis>
            </joint>

            <joint name='left_rear_wheel_joint' type='revolute'>
                <parent>chassis</parent>
                <child>left_rear_wheel</child>
                <axis>
                    <xyz>0 0 1</xyz>
                    <limit><lower>-1.79769e+308</lower><upper>1.79769e+308</upper></limit>
                </axis>
            </joint>

            <joint name='right_rear_wheel_joint' type='revolute'>
                <parent>chassis</parent>
                <child>right_rear_wheel</child>
                <axis>
                    <xyz>0 0 1</xyz>
                    <limit><lower>-1.79769e+308</lower><upper>1.79769e+308</upper></limit>
                </axis>
            </joint>

            <link name='lidar_link'>
                <pose relative_to='chassis'>0.8 0 0.5 0 0 0</pose>
                <inertial>
                    <mass>0.1</mass>
                    <inertia>
                        <ixx>0.000166667</ixx><iyy>0.000166667</iyy><izz>0.000166667</izz>
                    </inertia>
                </inertial>
                <visual name='visual'>
                    <geometry><cylinder><radius>0.05</radius><length>0.1</length></cylinder></geometry>
                    <material><ambient>0 0 0 1</ambient><diffuse>0 0 0 1</diffuse></material>
                </visual>
                <sensor name='gpu_lidar' type='gpu_lidar'>
                    <topic>lidar</topic>
                    <update_rate>10</update_rate>
                    <lidar>
                        <scan>
                            <horizontal>
                                <samples>640</samples>
                                <resolution>1</resolution>
                                <min_angle>-1.396263</min_angle>
                                <max_angle>1.396263</max_angle>
                            </horizontal>
                        </scan>
                        <range>
                            <min>0.08</min>
                            <max>10.0</max>
                        </range>
                    </lidar>
                    <visualize>true</visualize>
                </sensor>
            </link>

            <joint name='lidar_joint' type='fixed'>
                <parent>chassis</parent>
                <child>lidar_link</child>
            </joint>

            <plugin filename="gz-sim-diff-drive-system" name="gz::sim::systems::DiffDrive">
                <left_joint>left_front_wheel_joint</left_joint>
                <left_joint>left_rear_wheel_joint</left_joint>
                <right_joint>right_front_wheel_joint</right_joint>
                <right_joint>right_rear_wheel_joint</right_joint>
                <wheel_separation>1.2</wheel_separation>
                <wheel_radius>0.4</wheel_radius>
                <odom_publish_frequency>1</odom_publish_frequency>
                <topic>cmd_vel</topic>
            </plugin>
        </model>
    </world>
</sdf>